package com.kodilla.exception.test;

import java.io.IOException;

public class FirstChallenge {

    public double divide(double a, double b) throws ArithmeticException {
        if(b == 0){
            throw new ArithmeticException();
        }
        return a / b;
    }

    /**
     * This main can throw an ArithmeticException!!!
     *      *      * @param args
     */
    public static void main(String[] args) {

        FirstChallenge firstChallenge = new FirstChallenge();

         try {
             double result = firstChallenge.divide(3, 1);
             System.out.println("Result is " + result);
         } catch (ArithmeticException e) {
             System.out.println("Mno≈ºysz przez zero!");
         } finally {
             System.out.println("End program");
         }


        //System.out.println(result);

    }
}